2024-06-24 09:29:41,708 - INFO - auth:20 - ImmutableMultiDict([])
2024-06-24 09:36:41,765 - INFO - auth:20 - ImmutableMultiDict([])
2024-06-24 09:36:55,138 - INFO - auth:20 - {'phone': '17696021211', 'password': '11111111', 'confirm_password': '11111111'}
2024-06-24 09:37:53,496 - INFO - auth:20 - {'phone': '17696021211', 'password': '11111111', 'confirm_password': '11111111'}
2024-06-24 09:37:53,497 - ERROR - app:838 - Exception on /api/register [POST]
Traceback (most recent call last):
  File "/usr/local/python/3.10.13/lib/python3.10/site-packages/flask/app.py", line 1473, in wsgi_app
    response = self.full_dispatch_request()
  File "/usr/local/python/3.10.13/lib/python3.10/site-packages/flask/app.py", line 882, in full_dispatch_request
    rv = self.handle_user_exception(e)
  File "/usr/local/python/3.10.13/lib/python3.10/site-packages/flask/app.py", line 880, in full_dispatch_request
    rv = self.dispatch_request()
  File "/usr/local/python/3.10.13/lib/python3.10/site-packages/flask/app.py", line 865, in dispatch_request
    return self.ensure_sync(self.view_functions[rule.endpoint])(**view_args)  # type: ignore[no-any-return]
  File "/workspaces/red-crawler/app/views/auth.py", line 21, in register_view
    form = RegistrationForm(request.get_json())
  File "/usr/local/python/3.10.13/lib/python3.10/site-packages/wtforms/form.py", line 208, in __call__
    return type.__call__(cls, *args, **kwargs)
  File "/usr/local/python/3.10.13/lib/python3.10/site-packages/flask_wtf/form.py", line 73, in __init__
    super().__init__(formdata=formdata, **kwargs)
  File "/usr/local/python/3.10.13/lib/python3.10/site-packages/wtforms/form.py", line 286, in __init__
    self.process(formdata, obj, data=data, **kwargs)
  File "/usr/local/python/3.10.13/lib/python3.10/site-packages/wtforms/form.py", line 127, in process
    field.process(formdata, data, extra_filters=field_extra_filters)
  File "/usr/local/python/3.10.13/lib/python3.10/site-packages/wtforms/fields/core.py", line 327, in process
    self.raw_data = formdata.getlist(self.name)
AttributeError: 'dict' object has no attribute 'getlist'
2024-06-24 09:43:29,620 - INFO - auth:20 - {'phone': '17696021211', 'password': '11111111', 'confirm_password': '11111111'}
2024-06-24 09:43:29,622 - ERROR - app:838 - Exception on /api/register [POST]
Traceback (most recent call last):
  File "/usr/local/python/3.10.13/lib/python3.10/site-packages/flask/app.py", line 1473, in wsgi_app
    response = self.full_dispatch_request()
  File "/usr/local/python/3.10.13/lib/python3.10/site-packages/flask/app.py", line 882, in full_dispatch_request
    rv = self.handle_user_exception(e)
  File "/usr/local/python/3.10.13/lib/python3.10/site-packages/flask/app.py", line 880, in full_dispatch_request
    rv = self.dispatch_request()
  File "/usr/local/python/3.10.13/lib/python3.10/site-packages/flask/app.py", line 865, in dispatch_request
    return self.ensure_sync(self.view_functions[rule.endpoint])(**view_args)  # type: ignore[no-any-return]
  File "/workspaces/red-crawler/app/views/auth.py", line 27, in register_view
    form = RegistrationForm(form_data)
  File "/usr/local/python/3.10.13/lib/python3.10/site-packages/wtforms/form.py", line 208, in __call__
    return type.__call__(cls, *args, **kwargs)
  File "/usr/local/python/3.10.13/lib/python3.10/site-packages/flask_wtf/form.py", line 73, in __init__
    super().__init__(formdata=formdata, **kwargs)
  File "/usr/local/python/3.10.13/lib/python3.10/site-packages/wtforms/form.py", line 286, in __init__
    self.process(formdata, obj, data=data, **kwargs)
  File "/usr/local/python/3.10.13/lib/python3.10/site-packages/wtforms/form.py", line 127, in process
    field.process(formdata, data, extra_filters=field_extra_filters)
  File "/usr/local/python/3.10.13/lib/python3.10/site-packages/wtforms/fields/core.py", line 327, in process
    self.raw_data = formdata.getlist(self.name)
AttributeError: 'dict' object has no attribute 'getlist'
2024-06-24 09:44:42,533 - INFO - auth:26 - {'phone': '17696021211', 'password': '11111111', 'confirm_password': '11111111'}
2024-06-24 09:44:42,534 - ERROR - app:838 - Exception on /api/register [POST]
Traceback (most recent call last):
  File "/usr/local/python/3.10.13/lib/python3.10/site-packages/flask/app.py", line 1473, in wsgi_app
    response = self.full_dispatch_request()
  File "/usr/local/python/3.10.13/lib/python3.10/site-packages/flask/app.py", line 882, in full_dispatch_request
    rv = self.handle_user_exception(e)
  File "/usr/local/python/3.10.13/lib/python3.10/site-packages/flask/app.py", line 880, in full_dispatch_request
    rv = self.dispatch_request()
  File "/usr/local/python/3.10.13/lib/python3.10/site-packages/flask/app.py", line 865, in dispatch_request
    return self.ensure_sync(self.view_functions[rule.endpoint])(**view_args)  # type: ignore[no-any-return]
  File "/workspaces/red-crawler/app/views/auth.py", line 28, in register_view
    form = RegistrationForm(form_data)
  File "/usr/local/python/3.10.13/lib/python3.10/site-packages/wtforms/form.py", line 208, in __call__
    return type.__call__(cls, *args, **kwargs)
  File "/usr/local/python/3.10.13/lib/python3.10/site-packages/flask_wtf/form.py", line 73, in __init__
    super().__init__(formdata=formdata, **kwargs)
  File "/usr/local/python/3.10.13/lib/python3.10/site-packages/wtforms/form.py", line 286, in __init__
    self.process(formdata, obj, data=data, **kwargs)
  File "/usr/local/python/3.10.13/lib/python3.10/site-packages/wtforms/form.py", line 127, in process
    field.process(formdata, data, extra_filters=field_extra_filters)
  File "/usr/local/python/3.10.13/lib/python3.10/site-packages/wtforms/fields/core.py", line 327, in process
    self.raw_data = formdata.getlist(self.name)
AttributeError: 'dict' object has no attribute 'getlist'
2024-06-24 09:54:41,230 - INFO - auth:24 - {'phone': '17696021211', 'password': '11111111', 'confirm_password': '11111111'}
2024-06-25 03:00:42,787 - INFO - auth:24 - {'phone': '17696021211', 'password': '11111111', 'confirm_password': '11111111'}
2024-06-25 03:00:50,295 - ERROR - app:838 - Exception on /api/users [GET]
Traceback (most recent call last):
  File "/usr/local/python/3.10.13/lib/python3.10/site-packages/flask/app.py", line 1473, in wsgi_app
    response = self.full_dispatch_request()
  File "/usr/local/python/3.10.13/lib/python3.10/site-packages/flask/app.py", line 882, in full_dispatch_request
    rv = self.handle_user_exception(e)
  File "/usr/local/python/3.10.13/lib/python3.10/site-packages/flask/app.py", line 880, in full_dispatch_request
    rv = self.dispatch_request()
  File "/usr/local/python/3.10.13/lib/python3.10/site-packages/flask/app.py", line 865, in dispatch_request
    return self.ensure_sync(self.view_functions[rule.endpoint])(**view_args)  # type: ignore[no-any-return]
  File "/workspaces/red-crawler/app/views/user.py", line 10, in users_view
    return jsonify(users), 201
  File "/usr/local/python/3.10.13/lib/python3.10/site-packages/flask/json/__init__.py", line 170, in jsonify
    return current_app.json.response(*args, **kwargs)  # type: ignore[return-value]
  File "/usr/local/python/3.10.13/lib/python3.10/site-packages/flask/json/provider.py", line 214, in response
    f"{self.dumps(obj, **dump_args)}\n", mimetype=self.mimetype
  File "/usr/local/python/3.10.13/lib/python3.10/site-packages/flask/json/provider.py", line 179, in dumps
    return json.dumps(obj, **kwargs)
  File "/usr/local/python/3.10.13/lib/python3.10/json/__init__.py", line 238, in dumps
    **kw).encode(obj)
  File "/usr/local/python/3.10.13/lib/python3.10/json/encoder.py", line 199, in encode
    chunks = self.iterencode(o, _one_shot=True)
  File "/usr/local/python/3.10.13/lib/python3.10/json/encoder.py", line 257, in iterencode
    return _iterencode(o, 0)
  File "/usr/local/python/3.10.13/lib/python3.10/site-packages/flask/json/provider.py", line 121, in _default
    raise TypeError(f"Object of type {type(o).__name__} is not JSON serializable")
TypeError: Object of type User is not JSON serializable
2024-06-25 03:08:25,582 - ERROR - app:838 - Exception on /api/users [GET]
Traceback (most recent call last):
  File "/usr/local/python/3.10.13/lib/python3.10/site-packages/flask/app.py", line 1473, in wsgi_app
    response = self.full_dispatch_request()
  File "/usr/local/python/3.10.13/lib/python3.10/site-packages/flask/app.py", line 883, in full_dispatch_request
    return self.finalize_request(rv)
  File "/usr/local/python/3.10.13/lib/python3.10/site-packages/flask/app.py", line 902, in finalize_request
    response = self.make_response(rv)
  File "/usr/local/python/3.10.13/lib/python3.10/site-packages/flask/app.py", line 1193, in make_response
    rv = self.json.response(rv)
  File "/usr/local/python/3.10.13/lib/python3.10/site-packages/flask/json/provider.py", line 214, in response
    f"{self.dumps(obj, **dump_args)}\n", mimetype=self.mimetype
  File "/usr/local/python/3.10.13/lib/python3.10/site-packages/flask/json/provider.py", line 179, in dumps
    return json.dumps(obj, **kwargs)
  File "/usr/local/python/3.10.13/lib/python3.10/json/__init__.py", line 238, in dumps
    **kw).encode(obj)
  File "/usr/local/python/3.10.13/lib/python3.10/json/encoder.py", line 199, in encode
    chunks = self.iterencode(o, _one_shot=True)
  File "/usr/local/python/3.10.13/lib/python3.10/json/encoder.py", line 257, in iterencode
    return _iterencode(o, 0)
  File "/usr/local/python/3.10.13/lib/python3.10/site-packages/flask/json/provider.py", line 121, in _default
    raise TypeError(f"Object of type {type(o).__name__} is not JSON serializable")
TypeError: Object of type User is not JSON serializable
2024-06-25 03:12:04,312 - ERROR - app:838 - Exception on /api/users [GET]
Traceback (most recent call last):
  File "/usr/local/python/3.10.13/lib/python3.10/site-packages/flask/app.py", line 1473, in wsgi_app
    response = self.full_dispatch_request()
  File "/usr/local/python/3.10.13/lib/python3.10/site-packages/flask/app.py", line 882, in full_dispatch_request
    rv = self.handle_user_exception(e)
  File "/usr/local/python/3.10.13/lib/python3.10/site-packages/flask/app.py", line 880, in full_dispatch_request
    rv = self.dispatch_request()
  File "/usr/local/python/3.10.13/lib/python3.10/site-packages/flask/app.py", line 865, in dispatch_request
    return self.ensure_sync(self.view_functions[rule.endpoint])(**view_args)  # type: ignore[no-any-return]
  File "/workspaces/red-crawler/app/views/user.py", line 10, in users_view
    users = [jsonify(user) for user in users]
  File "/workspaces/red-crawler/app/views/user.py", line 10, in <listcomp>
    users = [jsonify(user) for user in users]
  File "/usr/local/python/3.10.13/lib/python3.10/site-packages/flask/json/__init__.py", line 170, in jsonify
    return current_app.json.response(*args, **kwargs)  # type: ignore[return-value]
  File "/usr/local/python/3.10.13/lib/python3.10/site-packages/flask/json/provider.py", line 214, in response
    f"{self.dumps(obj, **dump_args)}\n", mimetype=self.mimetype
  File "/usr/local/python/3.10.13/lib/python3.10/site-packages/flask/json/provider.py", line 179, in dumps
    return json.dumps(obj, **kwargs)
  File "/usr/local/python/3.10.13/lib/python3.10/json/__init__.py", line 238, in dumps
    **kw).encode(obj)
  File "/usr/local/python/3.10.13/lib/python3.10/json/encoder.py", line 199, in encode
    chunks = self.iterencode(o, _one_shot=True)
  File "/usr/local/python/3.10.13/lib/python3.10/json/encoder.py", line 257, in iterencode
    return _iterencode(o, 0)
  File "/usr/local/python/3.10.13/lib/python3.10/site-packages/flask/json/provider.py", line 121, in _default
    raise TypeError(f"Object of type {type(o).__name__} is not JSON serializable")
TypeError: Object of type User is not JSON serializable
2024-06-25 03:12:54,676 - ERROR - app:838 - Exception on /api/users [GET]
Traceback (most recent call last):
  File "/usr/local/python/3.10.13/lib/python3.10/site-packages/flask/app.py", line 1473, in wsgi_app
    response = self.full_dispatch_request()
  File "/usr/local/python/3.10.13/lib/python3.10/site-packages/flask/app.py", line 882, in full_dispatch_request
    rv = self.handle_user_exception(e)
  File "/usr/local/python/3.10.13/lib/python3.10/site-packages/flask/app.py", line 880, in full_dispatch_request
    rv = self.dispatch_request()
  File "/usr/local/python/3.10.13/lib/python3.10/site-packages/flask/app.py", line 865, in dispatch_request
    return self.ensure_sync(self.view_functions[rule.endpoint])(**view_args)  # type: ignore[no-any-return]
  File "/workspaces/red-crawler/app/views/user.py", line 10, in users_view
    users = [jsonify(user).data for user in users]
  File "/workspaces/red-crawler/app/views/user.py", line 10, in <listcomp>
    users = [jsonify(user).data for user in users]
  File "/usr/local/python/3.10.13/lib/python3.10/site-packages/flask/json/__init__.py", line 170, in jsonify
    return current_app.json.response(*args, **kwargs)  # type: ignore[return-value]
  File "/usr/local/python/3.10.13/lib/python3.10/site-packages/flask/json/provider.py", line 214, in response
    f"{self.dumps(obj, **dump_args)}\n", mimetype=self.mimetype
  File "/usr/local/python/3.10.13/lib/python3.10/site-packages/flask/json/provider.py", line 179, in dumps
    return json.dumps(obj, **kwargs)
  File "/usr/local/python/3.10.13/lib/python3.10/json/__init__.py", line 238, in dumps
    **kw).encode(obj)
  File "/usr/local/python/3.10.13/lib/python3.10/json/encoder.py", line 199, in encode
    chunks = self.iterencode(o, _one_shot=True)
  File "/usr/local/python/3.10.13/lib/python3.10/json/encoder.py", line 257, in iterencode
    return _iterencode(o, 0)
  File "/usr/local/python/3.10.13/lib/python3.10/site-packages/flask/json/provider.py", line 121, in _default
    raise TypeError(f"Object of type {type(o).__name__} is not JSON serializable")
TypeError: Object of type User is not JSON serializable
2024-06-25 03:15:05,724 - ERROR - app:838 - Exception on /api/users [GET]
Traceback (most recent call last):
  File "/usr/local/python/3.10.13/lib/python3.10/site-packages/flask/app.py", line 1473, in wsgi_app
    response = self.full_dispatch_request()
  File "/usr/local/python/3.10.13/lib/python3.10/site-packages/flask/app.py", line 882, in full_dispatch_request
    rv = self.handle_user_exception(e)
  File "/usr/local/python/3.10.13/lib/python3.10/site-packages/flask/app.py", line 880, in full_dispatch_request
    rv = self.dispatch_request()
  File "/usr/local/python/3.10.13/lib/python3.10/site-packages/flask/app.py", line 865, in dispatch_request
    return self.ensure_sync(self.view_functions[rule.endpoint])(**view_args)  # type: ignore[no-any-return]
  File "/workspaces/red-crawler/app/views/user.py", line 10, in users_view
    users = json.dumps(get_all())
  File "/usr/local/python/3.10.13/lib/python3.10/json/__init__.py", line 231, in dumps
    return _default_encoder.encode(obj)
  File "/usr/local/python/3.10.13/lib/python3.10/json/encoder.py", line 199, in encode
    chunks = self.iterencode(o, _one_shot=True)
  File "/usr/local/python/3.10.13/lib/python3.10/json/encoder.py", line 257, in iterencode
    return _iterencode(o, 0)
  File "/usr/local/python/3.10.13/lib/python3.10/json/encoder.py", line 179, in default
    raise TypeError(f'Object of type {o.__class__.__name__} '
TypeError: Object of type User is not JSON serializable
2024-06-25 06:08:28,015 - INFO - auth:24 - {'phone': '17696021211', 'password': '11111111', 'confirm_password': '11111111'}
2024-06-25 06:09:38,627 - INFO - auth:24 - {'phone': '17696021211', 'password': '11111111', 'confirm_password': '11111111'}
2024-06-25 06:25:36,559 - ERROR - app:838 - Exception on /api/users/1 [GET]
Traceback (most recent call last):
  File "/usr/local/python/3.10.13/lib/python3.10/site-packages/flask/app.py", line 1473, in wsgi_app
    response = self.full_dispatch_request()
  File "/usr/local/python/3.10.13/lib/python3.10/site-packages/flask/app.py", line 882, in full_dispatch_request
    rv = self.handle_user_exception(e)
  File "/usr/local/python/3.10.13/lib/python3.10/site-packages/flask/app.py", line 880, in full_dispatch_request
    rv = self.dispatch_request()
  File "/usr/local/python/3.10.13/lib/python3.10/site-packages/flask/app.py", line 865, in dispatch_request
    return self.ensure_sync(self.view_functions[rule.endpoint])(**view_args)  # type: ignore[no-any-return]
  File "/workspaces/red-crawler/app/views/user.py", line 15, in user_view
    user = User.query.first(id = user_id)
TypeError: Query.first() got an unexpected keyword argument 'id'
